<?xml version="1.0" ?>

<!--
# Copyright (c) 2023, ANTOBOT LTD.
# All rights reserved.

# # # # # # # # # # # # # # # # # # # # # # # # # # # # # # # # # # # # # # # # # # # # # # # # # # # # # # # # # # # # # 
# # # Code Description:     URDF for AntoBot Ant wheels
# Contact: william.eaton@antobot.ai
# # # #  # # # # # # # # # # # # # # # # # # # # # # # # # # # # # # # # # # # # # # # # # # # # # # # # # # # # # # # # #
-->



<robot xmlns:xacro="http://ros.org/wiki/xacro">

  <xacro:macro name="ant_wheel" 
               params="name:=''
                       originX:=''
                       originY:=''
                       originZ:=''
                       rotZ:=''
                       centreOffset:=''">



    <joint name="wheel_${name}_joint" type="continuous">
      <parent link="robot_base_link"/>
      <child link="wheel_${name}_link"/>
      <origin xyz="${originX} ${originY} ${originZ}" rpy="0 0 0"/>
      <axis xyz="0 1 0"/>
      <limit effort="300" velocity="100.0" />
      <dynamics damping="0.7" friction="0.1" />
    </joint>

    <link name="wheel_${name}_link">
      <visual>
        <geometry>
          <mesh filename="package://antobot_sim_description/meshes/ant_wheel.dae" scale="1 1 1" />          
        </geometry>
        <origin xyz="0 0 0" rpy="0 0 ${rotZ}"/>
      </visual>
      <collision>
        <geometry>
					<cylinder length="0.11" radius="0.16" />
				</geometry>
        <origin xyz="0 ${centreOffset} 0" rpy="${M_PI/2} 0 0" />
      </collision>
      <inertial>
        <mass value="2" />
        <origin xyz="0 0 0" />
        <inertia ixx="0.0576" ixy="0.0" ixz="0"
                 iyy="0.0576" iyz="0.0"
                 izz="0.0576" />
      </inertial>
    </link>  

    <gazebo reference="wheel_${name}_link">
      <collision>
        <surface>
          <friction>
            <ode>
              <mu>1.000000</mu>
              <mu2>1</mu2>
              <fdir1>1 0 0</fdir1>
              <slip1>0</slip1>
              <slip2>0</slip2>
            </ode>
          </friction>
          <bounce>
            <restitution_coefficient>0.5</restitution_coefficient>
            <threshold>0.1</threshold>
          </bounce>
          <contact>
            <ode>
              <soft_cfm>0.000000</soft_cfm>
              <soft_erp>0.200000</soft_erp>
              <kp>1000000000.000000</kp>
              <kd>1.000000</kd>
              <max_vel>100.000000</max_vel>
              <min_depth>0.01000</min_depth>
            </ode>
          </contact>
        </surface>
      </collision>
    </gazebo>
    <!--
    <transmission name="wheel_${name}_trans" type="SimpleTransmission">
      <type>transmission_interface/SimpleTransmission</type>
      <actuator name="wheel_${name}_motor">
        <mechanicalReduction>1</mechanicalReduction>
        <hardwareInterface>hardware_interface/VelocityJointInterface</hardwareInterface>
      </actuator>
      <joint name="wheel_${name}_joint">
        <hardwareInterface>hardware_interface/VelocityJointInterface</hardwareInterface>
      </joint>
    </transmission>  
    -->

  </xacro:macro>
</robot>
